Workbook

Sheet Rendimiento_Promedio_Comparació
B3: Comparación de Rendimiento Promedio entre computadoras (Fork) | J3: Comparación de Rendimiento Promedio entre computadoras (Posix) | R3: Comparación de Rendimiento Promedio entre computadoras (OpenMP)
B6: Computadora de Prueba | E6: PC 1 | F6: PC 2 | G6: PC 3 | H6: PC 4 | J6: Computadora de Prueba | M6: PC 1 | N6: PC 2 | O6: PC 3 | P6: PC 4 | R6: Computadora de Prueba | U6: PC 1 | V6: PC 2 | W6: PC 3 | X6: PC 4
B7: mmClasicaFork (s) | C7: 1000 | D7: 1 | E7: =Rendimiento_PC_1!D8 -> 6.3652745 | F7: =Rendimiento_PC_2!D8 -> 3.5755694 | G7: =Rendimiento_PC_3!D8 -> 4.4296479 | H7: =Rendimiento_PC_4!D8 -> 7.4553247 | J7: mmClasicaPosix (s) | K7: 1000 | L7: 1 | M7: =Rendimiento_PC_1!D23 -> 6.3001464 | N7: =Rendimiento_PC_2!D23 -> 3.1785436 | O7: =Rendimiento_PC_3!D23 -> 4.3784989 | P7: =Rendimiento_PC_4!D23 -> 7.413243 | R7: mmClasicaOpenMP (s) | S7: 1000 | T7: 1 | U7: =Rendimiento_PC_1!D38 -> 3.1521945 | V7: =Rendimiento_PC_2!D38 -> 0.85255323 | W7: =Rendimiento_PC_3!D38 -> 1.735568 | X7: =Rendimiento_PC_4!D38 -> 3.200791
D8: 2 | E8: =Rendimiento_PC_1!D9 -> 2.9683764 | F8: =Rendimiento_PC_2!D9 -> 2.3235633 | G8: =Rendimiento_PC_3!D9 -> 2.1563045 | H8: =Rendimiento_PC_4!D9 -> 3.5844654 | L8: 2 | M8: =Rendimiento_PC_1!D24 -> 3.030908 | N8: =Rendimiento_PC_2!D24 -> 1.8945678 | O8: =Rendimiento_PC_3!D24 -> 2.1949989 | P8: =Rendimiento_PC_4!D24 -> 3.513457 | T8: 2 | U8: =Rendimiento_PC_1!D39 -> 1.5447374 | V8: =Rendimiento_PC_2!D39 -> 0.55631907 | W8: =Rendimiento_PC_3!D39 -> 0.861166 | X8: =Rendimiento_PC_4!D39 -> 1.567099
D9: 4 | E9: =Rendimiento_PC_1!D10 -> 1.3426279 | F9: =Rendimiento_PC_2!D10 -> 1.5455961 | G9: =Rendimiento_PC_3!D10 -> 1.019896 | H9: =Rendimiento_PC_4!D10 -> 1.6352786 | L9: 4 | M9: =Rendimiento_PC_1!D25 -> 1.3686748 | N9: =Rendimiento_PC_2!D25 -> 1.2581265 | O9: =Rendimiento_PC_3!D25 -> 1.0250663 | P9: =Rendimiento_PC_4!D25 -> 1.666968 | T9: 4 | U9: =Rendimiento_PC_1!D40 -> 0.7526897 | V9: =Rendimiento_PC_2!D40 -> 0.4028276 | W9: =Rendimiento_PC_3!D40 -> 0.458044 | X9: =Rendimiento_PC_4!D40 -> 0.707923
D10: 8 | E10: =Rendimiento_PC_1!D11 -> 1.2998355 | F10: =Rendimiento_PC_2!D11 -> 0.9775389 | G10: =Rendimiento_PC_3!D11 -> 1.0115513 | H10: =Rendimiento_PC_4!D11 -> 1.8622389 | L10: 8 | M10: =Rendimiento_PC_1!D26 -> 1.3535814 | N10: =Rendimiento_PC_2!D26 -> 0.9482432 | O10: =Rendimiento_PC_3!D26 -> 0.99683217 | P10: =Rendimiento_PC_4!D26 -> 1.930338 | T10: 8 | U10: =Rendimiento_PC_1!D41 -> 0.72828893 | V10: =Rendimiento_PC_2!D41 -> 0.39467367 | W10: =Rendimiento_PC_3!D41 -> 0.432278 | X10: =Rendimiento_PC_4!D41 -> 1.161581
D11: 16 | E11: =Rendimiento_PC_1!D12 -> 1.3095806 | F11: =Rendimiento_PC_2!D12 -> 0.9014237 | G11: =Rendimiento_PC_3!D12 -> 1.0302299 | H11: =Rendimiento_PC_4!D12 -> 1.7101013 | L11: 16 | M11: =Rendimiento_PC_1!D27 -> 1.350206 | N11: =Rendimiento_PC_2!D27 -> 0.90739907 | O11: =Rendimiento_PC_3!D27 -> 0.98947897 | P11: =Rendimiento_PC_4!D27 -> 1.674198 | T11: 16 | U11: =Rendimiento_PC_1!D42 -> 0.7234354 | V11: =Rendimiento_PC_2!D42 -> 0.39026837 | W11: =Rendimiento_PC_3!D42 -> 0.370895 | X11: =Rendimiento_PC_4!D42 -> 1.052786
C12: 2000 | D12: 1 | E12: =Rendimiento_PC_1!D13 -> 74.927575 | F12: =Rendimiento_PC_2!D13 -> 29.572015 | G12: =Rendimiento_PC_3!D13 -> 48.328844 | H12: =Rendimiento_PC_4!D13 -> 85.013687 | K12: 2000 | L12: 1 | M12: =Rendimiento_PC_1!D28 -> 81.23123 | N12: =Rendimiento_PC_2!D28 -> 29.215939 | O12: =Rendimiento_PC_3!D28 -> 49.615454 | P12: =Rendimiento_PC_4!D28 -> 85.232048 | S12: 2000 | T12: 1 | U12: =Rendimiento_PC_1!D43 -> 66.743969 | V12: =Rendimiento_PC_2!D43 -> 11.179702 | W12: =Rendimiento_PC_3!D43 -> 40.393593 | X12: =Rendimiento_PC_4!D43 -> 52.240741
D13: 2 | E13: =Rendimiento_PC_1!D14 -> 39.319343 | F13: =Rendimiento_PC_2!D14 -> 17.681684 | G13: =Rendimiento_PC_3!D14 -> 24.904403 | H13: =Rendimiento_PC_4!D14 -> 38.241326 | L13: 2 | M13: =Rendimiento_PC_1!D29 -> 40.846752 | N13: =Rendimiento_PC_2!D29 -> 17.347332 | O13: =Rendimiento_PC_3!D29 -> 25.284004 | P13: =Rendimiento_PC_4!D29 -> 39.443482 | T13: 2 | U13: =Rendimiento_PC_1!D44 -> 34.838502 | V13: =Rendimiento_PC_2!D44 -> 7.131837 | W13: =Rendimiento_PC_3!D44 -> 20.890931 | X13: =Rendimiento_PC_4!D44 -> 25.877792
D14: 4 | E14: =Rendimiento_PC_1!D15 -> 19.664425 | F14: =Rendimiento_PC_2!D15 -> 11.737817 | G14: =Rendimiento_PC_3!D15 -> 12.400948 | H14: =Rendimiento_PC_4!D15 -> 16.38883 | L14: 4 | M14: =Rendimiento_PC_1!D30 -> 19.952039 | N14: =Rendimiento_PC_2!D30 -> 11.567781 | O14: =Rendimiento_PC_3!D30 -> 12.308007 | P14: =Rendimiento_PC_4!D30 -> 16.154829 | T14: 4 | U14: =Rendimiento_PC_1!D45 -> 17.170474 | V14: =Rendimiento_PC_2!D45 -> 4.8582227 | W14: =Rendimiento_PC_3!D45 -> 10.096516 | X14: =Rendimiento_PC_4!D45 -> 10.005186
D15: 8 | E15: =Rendimiento_PC_1!D16 -> 18.234213 | F15: =Rendimiento_PC_2!D16 -> 9.4147947 | G15: =Rendimiento_PC_3!D16 -> 11.578498 | H15: =Rendimiento_PC_4!D16 -> 22.328791 | L15: 8 | M15: =Rendimiento_PC_1!D31 -> 18.08505 | N15: =Rendimiento_PC_2!D31 -> 9.1983194 | O15: =Rendimiento_PC_3!D31 -> 11.396806 | P15: =Rendimiento_PC_4!D31 -> 21.340121 | T15: 8 | U15: =Rendimiento_PC_1!D46 -> 17.092134 | V15: =Rendimiento_PC_2!D46 -> 4.7284991 | W15: =Rendimiento_PC_3!D46 -> 9.824346 | X15: =Rendimiento_PC_4!D46 -> 22.242482
D16: 16 | E16: =Rendimiento_PC_1!D17 -> 18.246216 | F16: =Rendimiento_PC_2!D17 -> 10.330923 | G16: =Rendimiento_PC_3!D17 -> 11.460496 | H16: =Rendimiento_PC_4!D17 -> 21.576659 | L16: 16 | M16: =Rendimiento_PC_1!D32 -> 18.185675 | N16: =Rendimiento_PC_2!D32 -> 9.9061937 | O16: =Rendimiento_PC_3!D32 -> 11.130576 | P16: =Rendimiento_PC_4!D32 -> 20.584149 | T16: 16 | U16: =Rendimiento_PC_1!D47 -> 16.821455 | V16: =Rendimiento_PC_2!D47 -> 6.9262384 | W16: =Rendimiento_PC_3!D47 -> 9.065475 | X16: =Rendimiento_PC_4!D47 -> 22.836286
C17: 4000 | D17: 1 | E17: =Rendimiento_PC_1!D18 -> 889.82581 | F17: =Rendimiento_PC_2!D18 -> 253.53119 | G17: =Rendimiento_PC_3!D18 -> 663.00071 | H17: =Rendimiento_PC_4!D18 -> 966.4804 | K17: 4000 | L17: 1 | M17: =Rendimiento_PC_1!D33 -> 885.3836 | N17: =Rendimiento_PC_2!D33 -> 263.37017 | O17: =Rendimiento_PC_3!D33 -> 674.78324 | P17: =Rendimiento_PC_4!D33 -> 1025.9182 | S17: 4000 | T17: 1 | U17: =Rendimiento_PC_1!D48 -> 743.95393 | V17: =Rendimiento_PC_2!D48 -> 194.2735 | W17: =Rendimiento_PC_3!D48 -> 649.56256 | X17: =Rendimiento_PC_4!D48 -> 898.29678
D18: 2 | E18: =Rendimiento_PC_1!D19 -> 440.0283 | F18: =Rendimiento_PC_2!D19 -> 155.10739 | G18: =Rendimiento_PC_3!D19 -> 330.03593 | H18: =Rendimiento_PC_4!D19 -> 398.54521 | L18: 2 | M18: =Rendimiento_PC_1!D34 -> 441.22234 | N18: =Rendimiento_PC_2!D34 -> 155.23923 | O18: =Rendimiento_PC_3!D34 -> 335.44528 | P18: =Rendimiento_PC_4!D34 -> 433.64635 | T18: 2 | U18: =Rendimiento_PC_1!D49 -> 383.72532 | V18: =Rendimiento_PC_2!D49 -> 118.13 | W18: =Rendimiento_PC_3!D49 -> 319.05141 | X18: =Rendimiento_PC_4!D49 -> 460.25464
D19: 4 | E19: =Rendimiento_PC_1!D20 -> 225.93884 | F19: =Rendimiento_PC_2!D20 -> 106.07217 | G19: =Rendimiento_PC_3!D20 -> 161.7735 | H19: =Rendimiento_PC_4!D20 -> 190.59681 | L19: 4 | M19: =Rendimiento_PC_1!D35 -> 231.48738 | N19: =Rendimiento_PC_2!D35 -> 106.03231 | O19: =Rendimiento_PC_3!D35 -> 165.56758 | P19: =Rendimiento_PC_4!D35 -> 203.74315 | T19: 4 | U19: =Rendimiento_PC_1!D50 -> 196.26986 | V19: =Rendimiento_PC_2!D50 -> 83.233264 | W19: =Rendimiento_PC_3!D50 -> 155.84288 | X19: =Rendimiento_PC_4!D50 -> 217.25084
D20: 8 | E20: =Rendimiento_PC_1!D21 -> 221.1494 | F20: =Rendimiento_PC_2!D21 -> 109.55279 | G20: =Rendimiento_PC_3!D21 -> 159.41807 | H20: =Rendimiento_PC_4!D21 -> 232.58224 | L20: 8 | M20: =Rendimiento_PC_1!D36 -> 218.15663 | N20: =Rendimiento_PC_2!D36 -> 105.74211 | O20: =Rendimiento_PC_3!D36 -> 158.1208 | P20: =Rendimiento_PC_4!D36 -> 217.51367 | T20: 8 | U20: =Rendimiento_PC_1!D51 -> 200.54497 | V20: =Rendimiento_PC_2!D51 -> 81.244809 | W20: =Rendimiento_PC_3!D51 -> 157.0811 | X20: =Rendimiento_PC_4!D51 -> 249.07636
D21: 16 | E21: =Rendimiento_PC_1!D22 -> 233.26549 | F21: =Rendimiento_PC_2!D22 -> 109.47244 | G21: =Rendimiento_PC_3!D22 -> 162.29786 | H21: =Rendimiento_PC_4!D22 -> 268.32843 | L21: 16 | M21: =Rendimiento_PC_1!D37 -> 220.22913 | N21: =Rendimiento_PC_2!D37 -> 99.094983 | O21: =Rendimiento_PC_3!D37 -> 159.46165 | P21: =Rendimiento_PC_4!D37 -> 250.49819 | T21: 16 | U21: =Rendimiento_PC_1!D52 -> 190.33952 | V21: =Rendimiento_PC_2!D52 -> 84.494165 | W21: =Rendimiento_PC_3!D52 -> 166.22891 | X21: =Rendimiento_PC_4!D52 -> 269.26137

Sheet Rendimiento_PC_1
B4: Calculo de Rendimiento Promedio con Matrices e hilos definidos en segundos | F4: PC 1
B7: Matrices | C7: Hilos | D7: Promedio | E7: Iter1 | F7: Iter2 | G7: Iter3 | H7: Iter4 | I7: Iter5 | J7: Iter6 | K7: Iter7 | L7: Iter8 | M7: Iter9 | N7: Iter10 | O7: Iter11 | P7: Iter12 | Q7: Iter13 | R7: Iter14 | S7: Iter15 | T7: Iter16 | U7: Iter17 | V7: Iter18 | W7: Iter19 | X7: Iter20 | Y7: Iter21 | Z7: Iter22 | AA7: Iter23 | AB7: Iter24 | AC7: Iter25 | AD7: Iter26 | AE7: Iter27 | AF7: Iter28 | AG7: Iter29 | AH7: Iter30
A8: mmClasicaFork (s) | B8: 1000 | C8: 1 | D8: =AVERAGE(E8:AH8) -> 6.3652745 | E8: 6.639305 | F8: 6.651617 | G8: 6.650489 | H8: 6.559103 | I8: 6.666126 | J8: 6.328418 | K8: 6.658221 | L8: 6.21079 | M8: 6.585593 | N8: 6.32753 | O8: 6.32666 | P8: 6.581004 | Q8: 6.604913 | R8: 6.401733 | S8: 6.340262 | T8: 6.026471 | U8: 6.132151 | V8: 6.528703 | W8: 5.997535 | X8: 6.157306 | Y8: 5.799442 | Z8: 6.248419 | AA8: 6.280389 | AB8: 6.319613 | AC8: 6.244657 | AD8: 6.287627 | AE8: 6.29163 | AF8: 6.630345 | AG8: 6.241091 | AH8: 6.241091
C9: 2 | D9: =AVERAGE(E9:AH9) -> 2.9683764 | E9: 2.892111 | F9: 3.028039 | G9: 3.068453 | H9: 2.952592 | I9: 2.883954 | J9: 2.953457 | K9: 2.844942 | L9: 2.858745 | M9: 3.022191 | N9: 3.071166 | O9: 2.971138 | P9: 2.939551 | Q9: 2.987081 | R9: 3.157419 | S9: 3.013372 | T9: 2.964124 | U9: 2.912848 | V9: 3.031137 | W9: 2.841536 | X9: 3.057512 | Y9: 2.869283 | Z9: 2.881278 | AA9: 2.881069 | AB9: 3.127584 | AC9: 2.884819 | AD9: 2.854312 | AE9: 2.757823 | AF9: 3.164969 | AG9: 3.089394 | AH9: 3.089394
C10: 4 | D10: =AVERAGE(E10:AH10) -> 1.3426279 | E10: 1.296821 | F10: 1.339598 | G10: 1.309256 | H10: 1.334779 | I10: 1.340275 | J10: 1.323571 | K10: 1.310807 | L10: 1.369966 | M10: 1.304573 | N10: 1.466128 | O10: 1.500699 | P10: 1.401587 | Q10: 1.457093 | R10: 1.377226 | S10: 1.370328 | T10: 1.284094 | U10: 1.278649 | V10: 1.349705 | W10: 1.381922 | X10: 1.322578 | Y10: 1.270948 | Z10: 1.314109 | AA10: 1.284627 | AB10: 1.331088 | AC10: 1.247996 | AD10: 1.355748 | AE10: 1.325866 | AF10: 1.365854 | AG10: 1.331473 | AH10: 1.331473
C11: 8 | D11: =AVERAGE(E11:AH11) -> 1.2998355 | E11: 1.290555 | F11: 1.276095 | G11: 1.310225 | H11: 1.263006 | I11: 1.261854 | J11: 1.266532 | K11: 1.277827 | L11: 1.278367 | M11: 1.269839 | N11: 1.284428 | O11: 1.307213 | P11: 1.356263 | Q11: 1.335615 | R11: 1.285225 | S11: 1.254032 | T11: 1.299665 | U11: 1.258122 | V11: 1.279826 | W11: 1.345187 | X11: 1.289532 | Y11: 1.312882 | Z11: 1.302041 | AA11: 1.306351 | AB11: 1.326673 | AC11: 1.309685 | AD11: 1.308585 | AE11: 1.301962 | AF11: 1.369269 | AG11: 1.334104 | AH11: 1.334104
C12: 16 | D12: =AVERAGE(E12:AH12) -> 1.3095806 | E12: 1.295101 | F12: 1.279492 | G12: 1.389796 | H12: 1.281345 | I12: 1.332778 | J12: 1.326623 | K12: 1.315689 | L12: 1.276597 | M12: 1.281577 | N12: 1.297151 | O12: 1.305898 | P12: 1.288699 | Q12: 1.355923 | R12: 1.329656 | S12: 1.321615 | T12: 1.366365 | U12: 1.337862 | V12: 1.270439 | W12: 1.250059 | X12: 1.32065 | Y12: 1.334699 | Z12: 1.347482 | AA12: 1.261842 | AB12: 1.278558 | AC12: 1.35128 | AD12: 1.327658 | AE12: 1.340952 | AF12: 1.268485 | AG12: 1.276573 | AH12: 1.276573
B13: 2000 | C13: 1 | D13: =AVERAGE(E13:AH13) -> 74.927575 | E13: 72.016524 | F13: 75.234345 | G13: 73.580496 | H13: 73.640756 | I13: 73.209385 | J13: 72.4817 | K13: 74.562429 | L13: 73.074545 | M13: 75.397007 | N13: 76.262184 | O13: 74.535597 | P13: 74.522287 | Q13: 74.061614 | R13: 77.172762 | S13: 77.132754 | T13: 74.277893 | U13: 74.67193 | V13: 75.53648 | W13: 75.562222 | X13: 75.400165 | Y13: 75.91765 | Z13: 75.092878 | AA13: 75.646001 | AB13: 76.569371 | AC13: 76.014608 | AD13: 74.288378 | AE13: 74.933862 | AF13: 76.760319 | AG13: 75.13556 | AH13: 75.13556
C14: 2 | D14: =AVERAGE(E14:AH14) -> 39.319343 | E14: 38.257738 | F14: 37.844461 | G14: 37.31053 | H14: 36.731234 | I14: 36.703681 | J14: 36.694478 | K14: 36.861752 | L14: 36.811546 | M14: 36.893185 | N14: 37.633714 | O14: 38.346405 | P14: 38.928755 | Q14: 39.389047 | R14: 41.452784 | S14: 40.640784 | T14: 41.445627 | U14: 41.349828 | V14: 42.218983 | W14: 41.754226 | X14: 42.267232 | Y14: 40.720598 | Z14: 40.458034 | AA14: 40.103623 | AB14: 39.713116 | AC14: 39.677365 | AD14: 39.818651 | AE14: 39.539561 | AF14: 39.959243 | AG14: 40.027056 | AH14: 40.027056
C15: 4 | D15: =AVERAGE(E15:AH15) -> 19.664425 | E15: 19.434623 | F15: 19.597696 | G15: 19.544825 | H15: 19.539624 | I15: 19.747075 | J15: 19.666749 | K15: 19.739992 | L15: 19.608809 | M15: 19.710333 | N15: 19.655846 | O15: 19.453158 | P15: 19.491865 | Q15: 19.778605 | R15: 20.18954 | S15: 19.879211 | T15: 21.191439 | U15: 19.57482 | V15: 19.366398 | W15: 19.124593 | X15: 19.320011 | Y15: 19.30756 | Z15: 19.77461 | AA15: 19.695321 | AB15: 19.303097 | AC15: 19.877552 | AD15: 19.363056 | AE15: 19.707341 | AF15: 19.513671 | AG15: 19.887662 | AH15: 19.887662
C16: 8 | D16: =AVERAGE(E16:AH16) -> 18.234213 | E16: 17.848485 | F16: 18.117426 | G16: 18.486113 | H16: 18.321895 | I16: 18.260046 | J16: 18.543008 | K16: 18.54956 | L16: 18.694183 | M16: 18.181623 | N16: 18.297472 | O16: 18.468652 | P16: 18.561289 | Q16: 19.061351 | R16: 18.429178 | S16: 18.249103 | T16: 18.479971 | U16: 18.110546 | V16: 18.289841 | W16: 18.227077 | X16: 17.771145 | Y16: 18.130248 | Z16: 18.468606 | AA16: 18.029897 | AB16: 18.070754 | AC16: 17.970503 | AD16: 17.904706 | AE16: 18.033294 | AF16: 17.997959 | AG16: 17.736227 | AH16: 17.736227
C17: 16 | D17: =AVERAGE(E17:AH17) -> 18.246216 | E17: 17.499913 | F17: 17.662398 | G17: 17.954524 | H17: 19.535299 | I17: 18.108496 | J17: 18.20771 | K17: 18.057557 | L17: 18.103485 | M17: 18.764905 | N17: 17.902319 | O17: 17.808252 | P17: 18.809426 | Q17: 17.703299 | R17: 17.825938 | S17: 17.944592 | T17: 17.830773 | U17: 18.182361 | V17: 17.926443 | W17: 18.023217 | X17: 18.414727 | Y17: 18.132648 | Z17: 18.144396 | AA17: 18.0979 | AB17: 18.797701 | AC17: 19.027056 | AD17: 18.580302 | AE17: 18.734055 | AF17: 18.95028 | AG17: 18.32826 | AH17: 18.32826
B18: 4000 | C18: 1 | D18: =AVERAGE(E18:AH18) -> 889.82581 | E18: 834.32917 | F18: 838.22754 | G18: 909.85921 | H18: 921.05292 | I18: 892.23179 | J18: 848.13172 | K18: 867.98664 | L18: 863.47577 | M18: 890.38016 | N18: 914.82118 | O18: 901.69055 | P18: 895.45916 | Q18: 905.78466 | R18: 895.87156 | S18: 936.86569 | T18: 903.22733 | U18: 925.97803 | V18: 874.93197 | W18: 874.18389 | X18: 891.59797 | Y18: 906.57632 | Z18: 915.50062 | AA18: 892.60371 | AB18: 872.23896 | AC18: 876.75226 | AD18: 883.99367 | AE18: 886.26756 | AF18: 904.45326 | AG18: 885.15055 | AH18: 885.15055
C19: 2 | D19: =AVERAGE(E19:AH19) -> 440.0283 | E19: 440.32615 | F19: 421.19004 | G19: 427.638 | H19: 439.35068 | I19: 449.38256 | J19: 439.42989 | K19: 453.62408 | L19: 462.42826 | M19: 436.24307 | N19: 448.37021 | O19: 439.0487 | P19: 441.40672 | Q19: 435.86885 | R19: 426.76551 | S19: 431.48576 | T19: 439.12145 | U19: 428.80757 | V19: 441.68076 | W19: 447.2975 | X19: 434.51848 | Y19: 436.4824 | Z19: 437.51821 | AA19: 446.1266 | AB19: 448.66241 | AC19: 456.21208 | AD19: 442.06785 | AE19: 452.05639 | AF19: 443.37045 | AG19: 427.18418 | AH19: 427.18418
C20: 4 | D20: =AVERAGE(E20:AH20) -> 225.93884 | E20: 225.70042 | F20: 227.9068 | G20: 220.06305 | H20: 230.57071 | I20: 224.54398 | J20: 224.78706 | K20: 227.53987 | L20: 215.63417 | M20: 222.99189 | N20: 224.77574 | O20: 217.78564 | P20: 228.28157 | Q20: 223.63641 | R20: 223.89947 | S20: 227.02351 | T20: 223.3519 | U20: 217.92664 | V20: 225.98026 | W20: 224.10279 | X20: 227.39907 | Y20: 235.08025 | Z20: 223.37089 | AA20: 236.94929 | AB20: 230.79371 | AC20: 222.35332 | AD20: 236.19383 | AE20: 230.72205 | AF20: 222.7797 | AG20: 228.01057 | AH20: 228.01057
C21: 8 | D21: =AVERAGE(E21:AH21) -> 221.1494 | E21: 217.88948 | F21: 222.60354 | G21: 224.42341 | H21: 237.95713 | I21: 225.21691 | J21: 224.11313 | K21: 221.16663 | L21: 227.22961 | M21: 224.46099 | N21: 214.08338 | O21: 214.31182 | P21: 215.42683 | Q21: 212.84096 | R21: 222.74031 | S21: 222.19443 | T21: 213.13581 | U21: 224.35542 | V21: 225.75769 | W21: 209.88651 | X21: 216.7931 | Y21: 229.96747 | Z21: 212.32198 | AA21: 219.95786 | AB21: 224.45511 | AC21: 215.48606 | AD21: 225.22706 | AE21: 225.20602 | AF21: 218.23918 | AG21: 223.51708 | AH21: 223.51708
C22: 16 | D22: =AVERAGE(E22:AH22) -> 233.26549 | E22: 242.62969 | F22: 239.59304 | G22: 237.99531 | H22: 233.80448 | I22: 236.90647 | J22: 230.42804 | K22: 233.01909 | L22: 233.79572 | M22: 233.59159 | N22: 245.19378 | O22: 228.79527 | P22: 231.76229 | Q22: 240.05407 | R22: 220.91893 | S22: 228.23066 | T22: 236.5268 | U22: 229.73924 | V22: 236.5031 | W22: 228.13931 | X22: 232.2016 | Y22: 238.47658 | Z22: 232.96949 | AA22: 228.03968 | AB22: 232.0479 | AC22: 232.62774 | AD22: 229.72344 | AE22: 230.55858 | AF22: 226.56796 | AG22: 233.56241 | AH22: 233.56241
A23: mmClasicaPosix (s) | B23: 1000 | C23: 1 | D23: =AVERAGE(E23:AH23) -> 6.3001464 | E23: 6.481076 | F23: 6.414348 | G23: 6.123118 | H23: 6.669699 | I23: 6.248455 | J23: 6.338654 | K23: 6.15698 | L23: 6.137825 | M23: 6.303497 | N23: 6.199342 | O23: 6.18262 | P23: 6.161657 | Q23: 6.176852 | R23: 6.576729 | S23: 6.580172 | T23: 6.406962 | U23: 6.499209 | V23: 6.268832 | W23: 6.351365 | X23: 6.154427 | Y23: 6.371752 | Z23: 6.261563 | AA23: 6.230946 | AB23: 6.184533 | AC23: 6.243758 | AD23: 6.270078 | AE23: 6.285808 | AF23: 6.192937 | AG23: 6.290108 | AH23: 6.241091
C24: 2 | D24: =AVERAGE(E24:AH24) -> 3.030908 | E24: 3.075408 | F24: 3.040584 | G24: 2.94528 | H24: 3.120741 | I24: 2.963897 | J24: 2.966941 | K24: 2.944338 | L24: 3.017495 | M24: 3.199823 | N24: 3.159499 | O24: 3.031387 | P24: 3.087309 | Q24: 3.011261 | R24: 2.986198 | S24: 3.295802 | T24: 2.914677 | U24: 3.024904 | V24: 3.056916 | W24: 2.923291 | X24: 2.921807 | Y24: 2.933185 | Z24: 3.231014 | AA24: 2.943756 | AB24: 3.095347 | AC24: 3.036243 | AD24: 2.962493 | AE24: 2.975707 | AF24: 3.009976 | AG24: 2.962567 | AH24: 3.089394
C25: 4 | D25: =AVERAGE(E25:AH25) -> 1.3686748 | E25: 1.324602 | F25: 1.328442 | G25: 1.455152 | H25: 1.431907 | I25: 1.390334 | J25: 1.420962 | K25: 1.337463 | L25: 1.336942 | M25: 1.412487 | N25: 1.374553 | O25: 1.378293 | P25: 1.324813 | Q25: 1.327901 | R25: 1.408315 | S25: 1.352259 | T25: 1.411983 | U25: 1.338402 | V25: 1.401679 | W25: 1.454948 | X25: 1.393486 | Y25: 1.324248 | Z25: 1.370942 | AA25: 1.418806 | AB25: 1.374555 | AC25: 1.307686 | AD25: 1.323898 | AE25: 1.342073 | AF25: 1.317188 | AG25: 1.344453 | AH25: 1.331473
C26: 8 | D26: =AVERAGE(E26:AH26) -> 1.3535814 | E26: 1.427533 | F26: 1.314563 | G26: 1.303905 | H26: 1.389169 | I26: 1.418195 | J26: 1.352541 | K26: 1.376014 | L26: 1.381714 | M26: 1.325612 | N26: 1.319304 | O26: 1.34819 | P26: 1.343034 | Q26: 1.347828 | R26: 1.354838 | S26: 1.306121 | T26: 1.360248 | U26: 1.351954 | V26: 1.308058 | W26: 1.330973 | X26: 1.316022 | Y26: 1.431725 | Z26: 1.34673 | AA26: 1.298341 | AB26: 1.36327 | AC26: 1.388823 | AD26: 1.346466 | AE26: 1.39933 | AF26: 1.390411 | AG26: 1.332425 | AH26: 1.334104
C27: 16 | D27: =AVERAGE(E27:AH27) -> 1.350206 | E27: 1.299745 | F27: 1.304502 | G27: 1.325791 | H27: 1.335306 | I27: 1.298583 | J27: 1.362171 | K27: 1.314017 | L27: 1.339797 | M27: 1.367317 | N27: 1.372071 | O27: 1.375983 | P27: 1.410215 | Q27: 1.315973 | R27: 1.353865 | S27: 1.328104 | T27: 1.367284 | U27: 1.313036 | V27: 1.314608 | W27: 1.361992 | X27: 1.412562 | Y27: 1.292501 | Z27: 1.386588 | AA27: 1.374719 | AB27: 1.340619 | AC27: 1.407759 | AD27: 1.438313 | AE27: 1.391512 | AF27: 1.393876 | AG27: 1.330797 | AH27: 1.276573
B28: 2000 | C28: 1 | D28: =AVERAGE(E28:AH28) -> 81.23123 | E28: 84.083809 | F28: 79.495473 | G28: 79.57148 | H28: 81.128298 | I28: 81.351762 | J28: 82.130783 | K28: 82.625369 | L28: 83.289511 | M28: 83.305256 | N28: 80.36095 | O28: 82.250797 | P28: 81.067286 | Q28: 81.798346 | R28: 82.019242 | S28: 82.503521 | T28: 81.446635 | U28: 80.863879 | V28: 80.078082 | W28: 80.94171 | X28: 80.679562 | Y28: 81.725536 | Z28: 81.23397 | AA28: 81.101656 | AB28: 82.696577 | AC28: 81.509756 | AD28: 81.334552 | AE28: 80.582505 | AF28: 80.192795 | AG28: 80.432229 | AH28: 75.13556
C29: 2 | D29: =AVERAGE(E29:AH29) -> 40.846752 | E29: 40.214252 | F29: 41.239179 | G29: 40.767358 | H29: 41.010053 | I29: 41.308922 | J29: 40.940091 | K29: 41.960765 | L29: 42.046252 | M29: 40.941738 | N29: 40.641385 | O29: 39.723547 | P29: 39.597029 | Q29: 40.014284 | R29: 39.918807 | S29: 40.040736 | T29: 40.210443 | U29: 40.003658 | V29: 40.764456 | W29: 41.175126 | X29: 40.699799 | Y29: 41.357306 | Z29: 41.730166 | AA29: 41.599931 | AB29: 42.331376 | AC29: 42.257965 | AD29: 40.715178 | AE29: 40.535 | AF29: 40.90168 | AG29: 40.72903 | AH29: 40.027056
C30: 4 | D30: =AVERAGE(E30:AH30) -> 19.952039 | E30: 20.202222 | F30: 20.007526 | G30: 20.092376 | H30: 20.265203 | I30: 20.189721 | J30: 20.06943 | K30: 20.2726 | L30: 20.30693 | M30: 20.249277 | N30: 20.701501 | O30: 20.667325 | P30: 20.7298 | Q30: 20.911546 | R30: 21.66491 | S30: 20.521193 | T30: 20.825334 | U30: 20.688159 | V30: 21.062936 | W30: 17.538396 | X30: 19.11974 | Y30: 18.86367 | Z30: 18.660506 | AA30: 18.789513 | AB30: 20.184424 | AC30: 18.983307 | AD30: 19.323723 | AE30: 19.207131 | AF30: 19.409036 | AG30: 19.166082 | AH30: 19.887662
C31: 8 | D31: =AVERAGE(E31:AH31) -> 18.08505 | E31: 17.843873 | F31: 17.92376 | G31: 18.050195 | H31: 18.145874 | I31: 18.106845 | J31: 17.716276 | K31: 17.900883 | L31: 18.373977 | M31: 18.139093 | N31: 18.171378 | O31: 18.418046 | P31: 18.73562 | Q31: 18.182502 | R31: 18.409112 | S31: 18.670298 | T31: 19.436784 | U31: 18.513862 | V31: 18.617858 | W31: 18.269503 | X31: 17.884034 | Y31: 17.867569 | Z31: 18.070398 | AA31: 17.481835 | AB31: 17.774442 | AC31: 17.708629 | AD31: 17.422678 | AE31: 17.588512 | AF31: 17.792079 | AG31: 17.599343 | AH31: 17.736227
C32: 16 | D32: =AVERAGE(E32:AH32) -> 18.185675 | E32: 17.515925 | F32: 17.551093 | G32: 17.476126 | H32: 17.517795 | I32: 17.469711 | J32: 17.626827 | K32: 17.808499 | L32: 18.337372 | M32: 17.791743 | N32: 17.985804 | O32: 18.201469 | P32: 18.146118 | Q32: 19.710013 | R32: 18.112719 | S32: 18.008807 | T32: 17.811371 | U32: 17.773064 | V32: 18.063863 | W32: 18.206823 | X32: 18.08546 | Y32: 18.241571 | Z32: 18.309088 | AA32: 18.205921 | AB32: 18.384449 | AC32: 19.630846 | AD32: 19.039958 | AE32: 18.972355 | AF32: 18.746824 | AG32: 18.51038 | AH32: 18.32826
B33: 4000 | C33: 1 | D33: =AVERAGE(E33:AH33) -> 885.3836 | E33: 870.28673 | F33: 889.97713 | G33: 882.90612 | H33: 912.65328 | I33: 892.41072 | J33: 860.2868 | K33: 863.54303 | L33: 860.55432 | M33: 890.70244 | N33: 917.57867 | O33: 893.38715 | P33: 903.7222 | Q33: 882.77232 | R33: 869.7863 | S33: 896.86276 | T33: 886.08187 | U33: 886.74053 | V33: 897.41103 | W33: 877.82327 | X33: 878.48841 | Y33: 878.32416 | Z33: 916.8713 | AA33: 881.21937 | AB33: 877.67782 | AC33: 893.64816 | AD33: 870.06286 | AE33: 881.29784 | AF33: 873.47245 | AG33: 889.80851 | AH33: 885.15055
C34: 2 | D34: =AVERAGE(E34:AH34) -> 441.22234 | E34: 434.93646 | F34: 415.05122 | G34: 429.98542 | H34: 426.53103 | I34: 420.54084 | J34: 429.0235 | K34: 443.55924 | L34: 442.31181 | M34: 448.21019 | N34: 444.09643 | O34: 434.84872 | P34: 442.39177 | Q34: 430.53313 | R34: 422.53845 | S34: 434.80443 | T34: 429.08313 | U34: 422.39439 | V34: 423.69338 | W34: 426.69382 | X34: 435.77222 | Y34: 444.14788 | Z34: 432.59925 | AA34: 464.71678 | AB34: 493.45691 | AC34: 486.21431 | AD34: 468.52441 | AE34: 461.38635 | AF34: 454.60859 | AG34: 466.83193 | AH34: 427.18418
C35: 4 | D35: =AVERAGE(E35:AH35) -> 231.48738 | E35: 230.59685 | F35: 236.70045 | G35: 226.45021 | H35: 235.45738 | I35: 240.08874 | J35: 228.06034 | K35: 237.56943 | L35: 237.76072 | M35: 243.16348 | N35: 241.4916 | O35: 235.53468 | P35: 242.8262 | Q35: 245.90134 | R35: 229.74878 | S35: 231.24327 | T35: 236.08439 | U35: 226.14604 | V35: 231.36462 | W35: 233.37305 | X35: 225.39025 | Y35: 228.80543 | Z35: 232.70096 | AA35: 229.55296 | AB35: 227.98228 | AC35: 220.22672 | AD35: 221.10312 | AE35: 228.03664 | AF35: 211.12647 | AG35: 222.12434 | AH35: 228.01057
C36: 8 | D36: =AVERAGE(E36:AH36) -> 218.15663 | E36: 206.43415 | F36: 221.54359 | G36: 225.47484 | H36: 216.15086 | I36: 216.66072 | J36: 220.25575 | K36: 224.96923 | L36: 218.43949 | M36: 221.94856 | N36: 228.7882 | O36: 219.53417 | P36: 210.40661 | Q36: 214.82687 | R36: 211.60241 | S36: 217.38689 | T36: 217.91856 | U36: 218.78006 | V36: 214.64486 | W36: 217.13291 | X36: 218.12046 | Y36: 212.43118 | Z36: 217.32748 | AA36: 222.53925 | AB36: 224.65292 | AC36: 217.67179 | AD36: 219.51455 | AE36: 215.80248 | AF36: 209.09924 | AG36: 221.12369 | AH36: 223.51708
C37: 16 | D37: =AVERAGE(E37:AH37) -> 220.22913 | E37: 217.52804 | F37: 225.2873 | G37: 223.60269 | H37: 209.92357 | I37: 220.29103 | J37: 228.55791 | K37: 221.76953 | L37: 213.21526 | M37: 220.00228 | N37: 221.13166 | O37: 214.73414 | P37: 215.09465 | Q37: 217.60655 | R37: 212.13424 | S37: 216.11324 | T37: 224.88495 | U37: 215.28746 | V37: 218.43719 | W37: 217.25713 | X37: 218.63199 | Y37: 211.37135 | Z37: 221.23223 | AA37: 226.16903 | AB37: 217.53429 | AC37: 223.84812 | AD37: 231.87902 | AE37: 219.71108 | AF37: 224.68632 | AG37: 225.38916 | AH37: 233.56241
A38: mmClasicaOpenMP (s) | B38: 1000 | C38: 1 | D38: =AVERAGE(E38:AH38) -> 3.1521945 | E38: 3.349045 | F38: 3.408799 | G38: 2.961377 | H38: 2.801953 | I38: 3.096543 | J38: 3.008379 | K38: 2.895144 | L38: 3.094603 | M38: 2.870346 | N38: 3.380322 | O38: 3.242035 | P38: 3.203737 | Q38: 2.781612 | R38: 3.184879 | S38: 3.577353 | T38: 2.843339 | U38: 2.936552 | V38: 3.666023 | W38: 2.851069 | X38: 2.839985 | Y38: 3.34349 | Z38: 3.227842 | AA38: 2.927311 | AB38: 3.655107 | AC38: 3.495 | AD38: 3.614837 | AE38: 2.790902 | AF38: 2.975461 | AG38: 3.201855 | AH38: 3.340936
C39: 2 | D39: =AVERAGE(E39:AH39) -> 1.5447374 | E39: 1.7528 | F39: 1.644746 | G39: 1.707857 | H39: 1.393369 | I39: 1.427471 | J39: 1.470967 | K39: 1.394268 | L39: 1.654805 | M39: 1.3713 | N39: 1.375546 | O39: 1.366342 | P39: 1.646322 | Q39: 1.539269 | R39: 1.567149 | S39: 1.470763 | T39: 1.510606 | U39: 1.460945 | V39: 1.374853 | W39: 1.557516 | X39: 1.67647 | Y39: 1.409587 | Z39: 1.544356 | AA39: 1.614834 | AB39: 1.848633 | AC39: 1.763107 | AD39: 1.627474 | AE39: 1.41537 | AF39: 1.444996 | AG39: 1.799379 | AH39: 1.511022
C40: 4 | D40: =AVERAGE(E40:AH40) -> 0.7526897 | E40: 0.683568 | F40: 0.90446 | G40: 0.828018 | H40: 0.713305 | I40: 0.688357 | J40: 0.844089 | K40: 0.7288 | L40: 0.711493 | M40: 0.826468 | N40: 0.809318 | O40: 0.791466 | P40: 0.724315 | Q40: 0.800796 | R40: 0.819757 | S40: 0.7207 | T40: 0.737815 | U40: 0.849647 | V40: 0.702926 | W40: 0.679524 | X40: 0.657851 | Y40: 0.65825 | Z40: 0.683712 | AA40: 0.75956 | AB40: 0.686595 | AC40: 0.763209 | AD40: 0.773527 | AE40: 0.713988 | AF40: 0.773495 | AG40: 0.713074 | AH40: 0.832608
C41: 8 | D41: =AVERAGE(E41:AH41) -> 0.72828893 | E41: 0.656014 | F41: 0.822503 | G41: 0.704961 | H41: 0.724382 | I41: 0.665985 | J41: 0.683459 | K41: 0.817938 | L41: 0.807671 | M41: 0.854613 | N41: 0.686827 | O41: 0.716001 | P41: 0.672295 | Q41: 0.72123 | R41: 0.680922 | S41: 0.656098 | T41: 0.701518 | U41: 0.800841 | V41: 0.778861 | W41: 0.783499 | X41: 0.770408 | Y41: 0.718845 | Z41: 0.672744 | AA41: 0.675281 | AB41: 0.6549 | AC41: 0.752603 | AD41: 0.837535 | AE41: 0.671813 | AF41: 0.689725 | AG41: 0.809075 | AH41: 0.660121
C42: 16 | D42: =AVERAGE(E42:AH42) -> 0.7234354 | E42: 0.831419 | F42: 0.846904 | G42: 0.74547 | H42: 0.69216 | I42: 0.780783 | J42: 0.638834 | K42: 0.700818 | L42: 0.674456 | M42: 0.666121 | N42: 0.649626 | O42: 0.813579 | P42: 0.774542 | Q42: 0.805845 | R42: 0.81822 | S42: 0.831139 | T42: 0.702272 | U42: 0.68318 | V42: 0.746776 | W42: 0.772812 | X42: 0.723003 | Y42: 0.651563 | Z42: 0.693035 | AA42: 0.640038 | AB42: 0.638862 | AC42: 0.678607 | AD42: 0.730212 | AE42: 0.694207 | AF42: 0.64588 | AG42: 0.693803 | AH42: 0.738896
B43: 2000 | C43: 1 | D43: =AVERAGE(E43:AH43) -> 66.743969 | E43: 65.204164 | F43: 65.857845 | G43: 64.548998 | H43: 66.070724 | I43: 64.858646 | J43: 64.856417 | K43: 65.329735 | L43: 65.736049 | M43: 66.066939 | N43: 67.385737 | O43: 66.454326 | P43: 68.825994 | Q43: 66.330107 | R43: 66.31133 | S43: 65.933979 | T43: 65.685903 | U43: 65.889679 | V43: 67.580396 | W43: 66.553364 | X43: 67.888682 | Y43: 67.874933 | Z43: 66.853245 | AA43: 66.875888 | AB43: 68.372934 | AC43: 67.640822 | AD43: 67.26227 | AE43: 68.932367 | AF43: 67.845849 | AG43: 68.626499 | AH43: 68.665254
C44: 2 | D44: =AVERAGE(E44:AH44) -> 34.838502 | E44: 35.541847 | F44: 34.661087 | G44: 34.445795 | H44: 34.292352 | I44: 34.458505 | J44: 34.430827 | K44: 34.739259 | L44: 34.938109 | M44: 35.605536 | N44: 34.933483 | O44: 35.213293 | P44: 35.588448 | Q44: 36.13256 | R44: 35.816811 | S44: 36.636373 | T44: 35.923224 | U44: 36.160491 | V44: 36.442079 | W44: 35.793751 | X44: 35.373031 | Y44: 34.098119 | Z44: 33.390368 | AA44: 33.987586 | AB44: 33.865826 | AC44: 32.960125 | AD44: 33.400097 | AE44: 34.205118 | AF44: 33.878839 | AG44: 34.090963 | AH44: 34.151156
C45: 4 | D45: =AVERAGE(E45:AH45) -> 17.170474 | E45: 16.999286 | F45: 17.186765 | G45: 17.389196 | H45: 17.530324 | I45: 17.24716 | J45: 17.446703 | K45: 18.702457 | L45: 17.805347 | M45: 17.549329 | N45: 17.466532 | O45: 17.538355 | P45: 17.433284 | Q45: 17.371705 | R45: 17.475779 | S45: 17.566265 | T45: 17.740884 | U45: 18.153221 | V45: 17.682381 | W45: 17.764866 | X45: 16.606317 | Y45: 16.478346 | Z45: 16.740637 | AA45: 16.350958 | AB45: 16.265955 | AC45: 16.403124 | AD45: 16.333416 | AE45: 16.380255 | AF45: 16.279477 | AG45: 16.673046 | AH45: 16.552851
...

Sheet Rendimiento_PC_2
B4: Calculo de Rendimiento Promedio con Matrices e hilos definidos en segundos | F4: PC 2
B7: Matrices | C7: Hilos | D7: Promedio | E7: Iter1 | F7: Iter2 | G7: Iter3 | H7: Iter4 | I7: Iter5 | J7: Iter6 | K7: Iter7 | L7: Iter8 | M7: Iter9 | N7: Iter10 | O7: Iter11 | P7: Iter12 | Q7: Iter13 | R7: Iter14 | S7: Iter15 | T7: Iter16 | U7: Iter17 | V7: Iter18 | W7: Iter19 | X7: Iter20 | Y7: Iter21 | Z7: Iter22 | AA7: Iter23 | AB7: Iter24 | AC7: Iter25 | AD7: Iter26 | AE7: Iter27 | AF7: Iter28 | AG7: Iter29 | AH7: Iter30
A8: mmClasicaFork (s) | B8: 1000 | C8: 1 | D8: =AVERAGE(E8:AH8) -> 3.5755694 | E8: 3.801789 | F8: 3.149411 | G8: 3.092237 | H8: 3.357928 | I8: 3.433477 | J8: 3.236163 | K8: 3.613284 | L8: 3.266973 | M8: 3.307148 | N8: 3.176918 | O8: 3.149938 | P8: 3.133686 | Q8: 3.205588 | R8: 3.134361 | S8: 3.199763 | T8: 3.212571 | U8: 3.720775 | V8: 3.438175 | W8: 3.312071 | X8: 3.653585 | Y8: 3.877446 | Z8: 4.100338 | AA8: 4.798439 | AB8: 4.265138 | AC8: 4.517902 | AD8: 3.676478 | AE8: 4.053041 | AF8: 3.76806 | AG8: 3.675522 | AH8: 3.938877
C9: 2 | D9: =AVERAGE(E9:AH9) -> 2.3235633 | E9: 2.386214 | F9: 2.189956 | G9: 2.147325 | H9: 2.086615 | I9: 2.235871 | J9: 2.574748 | K9: 2.574449 | L9: 2.881112 | M9: 2.576063 | N9: 2.230341 | O9: 2.04442 | P9: 2.414336 | Q9: 2.365258 | R9: 2.207879 | S9: 2.335044 | T9: 2.37394 | U9: 2.358635 | V9: 2.31707 | W9: 2.511427 | X9: 2.660577 | Y9: 2.165158 | Z9: 2.12039 | AA9: 1.907447 | AB9: 2.020805 | AC9: 2.661009 | AD9: 2.420536 | AE9: 2.258877 | AF9: 2.128605 | AG9: 2.128484 | AH9: 2.424308
C10: 4 | D10: =AVERAGE(E10:AH10) -> 1.5455961 | E10: 1.478469 | F10: 1.295904 | G10: 1.272093 | H10: 1.286773 | I10: 1.259907 | J10: 1.858142 | K10: 1.51888 | L10: 1.825013 | M10: 2.144135 | N10: 1.959006 | O10: 1.792709 | P10: 1.57201 | Q10: 1.497339 | R10: 1.789927 | S10: 1.538015 | T10: 1.608446 | U10: 1.307084 | V10: 1.332128 | W10: 1.494701 | X10: 1.577326 | Y10: 1.738913 | Z10: 1.468054 | AA10: 1.805229 | AB10: 1.518672 | AC10: 1.486618 | AD10: 1.310061 | AE10: 1.45406 | AF10: 1.295812 | AG10: 1.348807 | AH10: 1.53365
C11: 8 | D11: =AVERAGE(E11:AH11) -> 0.9775389 | E11: 0.97229 | F11: 0.966982 | G11: 0.970941 | H11: 0.989764 | I11: 0.97033 | J11: 0.960613 | K11: 0.98227 | L11: 0.975924 | M11: 0.971954 | N11: 0.953761 | O11: 0.964523 | P11: 0.987134 | Q11: 0.973567 | R11: 0.962028 | S11: 0.97459 | T11: 0.97054 | U11: 0.970796 | V11: 0.978944 | W11: 0.975632 | X11: 0.974349 | Y11: 0.966648 | Z11: 0.952119 | AA11: 0.959351 | AB11: 1.073672 | AC11: 0.964686 | AD11: 1.045024 | AE11: 1.021299 | AF11: 0.977749 | AG11: 0.955779 | AH11: 0.962908
C12: 16 | D12: =AVERAGE(E12:AH12) -> 0.9014237 | E12: 0.899923 | F12: 0.902372 | G12: 0.894319 | H12: 0.897581 | I12: 0.91631 | J12: 0.893878 | K12: 0.887217 | L12: 0.910433 | M12: 0.899985 | N12: 0.895755 | O12: 0.890565 | P12: 0.909732 | Q12: 0.901451 | R12: 0.886078 | S12: 0.966936 | T12: 0.941826 | U12: 0.895229 | V12: 0.895338 | W12: 0.915758 | X12: 0.904266 | Y12: 0.899901 | Z12: 0.902302 | AA12: 0.894515 | AB12: 0.89207 | AC12: 0.895792 | AD12: 0.896433 | AE12: 0.899103 | AF12: 0.883797 | AG12: 0.891197 | AH12: 0.882649
B13: 2000 | C13: 1 | D13: =AVERAGE(E13:AH13) -> 29.572015 | E13: 28.942533 | F13: 28.593621 | G13: 28.677453 | H13: 28.783961 | I13: 28.734591 | J13: 28.816471 | K13: 28.759901 | L13: 28.703109 | M13: 28.734536 | N13: 28.601906 | O13: 28.769228 | P13: 28.55397 | Q13: 32.115859 | R13: 32.662407 | S13: 31.801701 | T13: 31.235548 | U13: 31.460055 | V13: 30.150111 | W13: 30.682982 | X13: 29.296498 | Y13: 29.242402 | Z13: 29.245716 | AA13: 29.314111 | AB13: 29.156185 | AC13: 29.337524 | AD13: 29.297034 | AE13: 29.171661 | AF13: 29.2686 | AG13: 29.827989 | AH13: 29.222782
C14: 2 | D14: =AVERAGE(E14:AH14) -> 17.681684 | E14: 17.686201 | F14: 17.727544 | G14: 17.599403 | H14: 17.686889 | I14: 17.715243 | J14: 17.713724 | K14: 17.651423 | L14: 17.783749 | M14: 17.727194 | N14: 17.719209 | O14: 19.900303 | P14: 21.164407 | Q14: 17.541349 | R14: 17.315064 | S14: 17.421625 | T14: 17.360109 | U14: 17.423647 | V14: 17.353024 | W14: 17.367294 | X14: 17.384349 | Y14: 17.548907 | Z14: 17.307442 | AA14: 17.552819 | AB14: 17.263261 | AC14: 17.240628 | AD14: 17.213135 | AE14: 17.208575 | AF14: 17.268649 | AG14: 17.337413 | AH14: 17.26794
C15: 4 | D15: =AVERAGE(E15:AH15) -> 11.737817 | E15: 11.676335 | F15: 11.695605 | G15: 11.557637 | H15: 11.598491 | I15: 11.627149 | J15: 11.639205 | K15: 11.645049 | L15: 11.602683 | M15: 11.571287 | N15: 11.607904 | O15: 11.657988 | P15: 11.704784 | Q15: 11.68011 | R15: 11.593932 | S15: 11.593083 | T15: 11.714822 | U15: 11.59647 | V15: 11.601571 | W15: 11.66301 | X15: 11.672769 | Y15: 11.618226 | Z15: 11.610809 | AA15: 11.563207 | AB15: 11.731893 | AC15: 11.891679 | AD15: 13.790671 | AE15: 12.083372 | AF15: 11.891524 | AG15: 11.581875 | AH15: 11.671381
C16: 8 | D16: =AVERAGE(E16:AH16) -> 9.4147947 | E16: 9.253556 | F16: 9.334452 | G16: 9.226743 | H16: 9.325757 | I16: 9.312977 | J16: 9.311503 | K16: 9.510231 | L16: 9.249604 | M16: 9.211182 | N16: 9.281576 | O16: 9.433732 | P16: 9.264008 | Q16: 9.312601 | R16: 9.454493 | S16: 9.45003 | T16: 9.434972 | U16: 9.247363 | V16: 9.414711 | W16: 9.370151 | X16: 9.453858 | Y16: 9.522151 | Z16: 9.314871 | AA16: 9.486008 | AB16: 9.668567 | AC16: 9.573683 | AD16: 9.532456 | AE16: 9.601908 | AF16: 9.906268 | AG16: 9.555033 | AH16: 9.429397
C17: 16 | D17: =AVERAGE(E17:AH17) -> 10.330923 | E17: 10.119739 | F17: 10.271737 | G17: 10.080802 | H17: 10.224361 | I17: 11.130386 | J17: 10.990696 | K17: 11.439664 | L17: 10.529315 | M17: 10.264394 | N17: 10.236045 | O17: 10.191679 | P17: 10.436329 | Q17: 10.266923 | R17: 10.245082 | S17: 10.318814 | T17: 10.187397 | U17: 10.277484 | V17: 10.432508 | W17: 10.248218 | X17: 10.139044 | Y17: 10.226327 | Z17: 10.143763 | AA17: 10.23042 | AB17: 10.222338 | AC17: 10.20568 | AD17: 10.280134 | AE17: 10.22184 | AF17: 10.136316 | AG17: 10.129579 | AH17: 10.100682
B18: 4000 | C18: 1 | D18: =AVERAGE(E18:AH18) -> 253.53119 | E18: 249.9854 | F18: 250.43726 | G18: 248.83642 | H18: 252.58025 | I18: 249.06462 | J18: 252.00781 | K18: 249.97294 | L18: 249.69475 | M18: 255.20024 | N18: 251.71549 | O18: 252.94088 | P18: 276.45737 | Q18: 256.61398 | R18: 247.67559 | S18: 250.02404 | T18: 254.95837 | U18: 248.94495 | V18: 253.98009 | W18: 247.90965 | X18: 247.53427 | Y18: 249.71962 | Z18: 267.73343 | AA18: 254.12105 | AB18: 255.3752 | AC18: 255.12628 | AD18: 253.21146 | AE18: 254.03481 | AF18: 256.9342 | AG18: 255.19937 | AH18: 257.94597
C19: 2 | D19: =AVERAGE(E19:AH19) -> 155.10739 | E19: 155.20666 | F19: 154.74424 | G19: 153.03878 | H19: 152.16968 | I19: 152.91997 | J19: 153.16021 | K19: 153.09558 | L19: 153.39058 | M19: 152.98155 | N19: 152.65677 | O19: 157.25982 | P19: 160.9234 | Q19: 153.49355 | R19: 158.6822 | S19: 152.5979 | T19: 154.87088 | U19: 153.13468 | V19: 154.83779 | W19: 153.98043 | X19: 153.06626 | Y19: 154.38655 | Z19: 153.36163 | AA19: 159.36003 | AB19: 152.42736 | AC19: 152.5119 | AD19: 153.16045 | AE19: 169.56439 | AF19: 162.68957 | AG19: 157.84738 | AH19: 151.70139
C20: 4 | D20: =AVERAGE(E20:AH20) -> 106.07217 | E20: 105.27767 | F20: 105.95481 | G20: 107.75777 | H20: 106.1495 | I20: 105.03354 | J20: 105.11678 | K20: 106.56203 | L20: 107.37858 | M20: 105.04998 | N20: 105.81457 | O20: 105.83863 | P20: 106.89625 | Q20: 106.65226 | R20: 105.19609 | S20: 106.81617 | T20: 105.73928 | U20: 105.47068 | V20: 106.30864 | W20: 106.57405 | X20: 105.2121 | Y20: 105.93112 | Z20: 105.5398 | AA20: 105.80567 | AB20: 106.90106 | AC20: 107.88767 | AD20: 105.59037 | AE20: 105.33737 | AF20: 107.01221 | AG20: 105.70618 | AH20: 105.65421
C21: 8 | D21: =AVERAGE(E21:AH21) -> 109.55279 | E21: 111.4132 | F21: 110.20092 | G21: 108.2572 | H21: 109.30495 | I21: 108.7984 | J21: 109.24337 | K21: 107.38366 | L21: 111.36493 | M21: 110.03723 | N21: 108.47482 | O21: 108.84226 | P21: 110.20424 | Q21: 109.32327 | R21: 110.84935 | S21: 108.85342 | T21: 108.57651 | U21: 109.52622 | V21: 108.93136 | W21: 106.71832 | X21: 109.71714 | Y21: 110.10637 | Z21: 108.69931 | AA21: 110.38889 | AB21: 108.29411 | AC21: 108.11613 | AD21: 111.94687 | AE21: 115.49817 | AF21: 108.89939 | AG21: 110.19983 | AH21: 108.41398
C22: 16 | D22: =AVERAGE(E22:AH22) -> 109.47244 | E22: 108.93311 | F22: 109.22942 | G22: 109.46382 | H22: 109.85726 | I22: 110.15197 | J22: 109.88212 | K22: 108.78418 | L22: 109.19985 | M22: 109.6007 | N22: 109.05632 | O22: 109.42546 | P22: 109.2704 | Q22: 109.43372 | R22: 108.77878 | S22: 109.89642 | T22: 109.46859 | U22: 108.94207 | V22: 109.0721 | W22: 109.0207 | X22: 109.60728 | Y22: 109.33129 | Z22: 111.31652 | AA22: 109.47109 | AB22: 109.32144 | AC22: 109.00967 | AD22: 109.60294 | AE22: 109.58726 | AF22: 110.11412 | AG22: 109.7976 | AH22: 109.54709
A23: mmClasicaPosix (s) | B23: 1000 | C23: 1 | D23: =AVERAGE(E23:AH23) -> 3.1785436 | E23: 3.158809 | F23: 3.172131 | G23: 3.210283 | H23: 3.299056 | I23: 3.226729 | J23: 3.123254 | K23: 3.233529 | L23: 3.176477 | M23: 3.155858 | N23: 3.128722 | O23: 3.116021 | P23: 3.148685 | Q23: 3.122263 | R23: 3.152277 | S23: 3.209275 | T23: 3.130843 | U23: 3.201926 | V23: 3.283147 | W23: 3.152292 | X23: 3.144063 | Y23: 3.143521 | Z23: 3.140483 | AA23: 3.12409 | AB23: 3.169819 | AC23: 3.144952 | AD23: 3.244167 | AE23: 3.18785 | AF23: 3.139666 | AG23: 3.29452 | AH23: 3.2216
C24: 2 | D24: =AVERAGE(E24:AH24) -> 1.8945678 | E24: 1.894709 | F24: 1.887508 | G24: 1.907575 | H24: 1.916655 | I24: 1.883785 | J24: 1.911259 | K24: 1.910347 | L24: 1.888887 | M24: 1.973338 | N24: 1.888813 | O24: 1.900669 | P24: 1.877861 | Q24: 1.889919 | R24: 1.879441 | S24: 1.858926 | T24: 1.886871 | U24: 1.885735 | V24: 1.859057 | W24: 1.858761 | X24: 1.872204 | Y24: 1.884856 | Z24: 1.880324 | AA24: 1.93024 | AB24: 1.901987 | AC24: 1.900603 | AD24: 1.947026 | AE24: 1.90092 | AF24: 1.895809 | AG24: 1.879869 | AH24: 1.883081
C25: 4 | D25: =AVERAGE(E25:AH25) -> 1.2581265 | E25: 1.253149 | F25: 1.249882 | G25: 1.257518 | H25: 1.250571 | I25: 1.241774 | J25: 1.250607 | K25: 1.251327 | L25: 1.246709 | M25: 1.24842 | N25: 1.256603 | O25: 1.259762 | P25: 1.25281 | Q25: 1.254605 | R25: 1.249937 | S25: 1.337396 | T25: 1.257252 | U25: 1.24328 | V25: 1.279448 | W25: 1.252842 | X25: 1.260335 | Y25: 1.249146 | Z25: 1.258017 | AA25: 1.261225 | AB25: 1.256606 | AC25: 1.263318 | AD25: 1.262934 | AE25: 1.26452 | AF25: 1.261965 | AG25: 1.257865 | AH25: 1.253972
C26: 8 | D26: =AVERAGE(E26:AH26) -> 0.9482432 | E26: 0.952829 | F26: 0.954622 | G26: 0.9459 | H26: 0.930701 | I26: 0.940613 | J26: 0.936024 | K26: 0.929012 | L26: 0.945239 | M26: 0.960264 | N26: 0.938586 | O26: 1.042261 | P26: 0.940899 | Q26: 0.949667 | R26: 0.945348 | S26: 0.959214 | T26: 0.946012 | U26: 0.941856 | V26: 0.938481 | W26: 0.950619 | X26: 0.929668 | Y26: 0.95221 | Z26: 0.937553 | AA26: 0.94359 | AB26: 0.94037 | AC26: 0.958671 | AD26: 0.960214 | AE26: 0.939816 | AF26: 0.952081 | AG26: 0.944828 | AH26: 0.940148
C27: 16 | D27: =AVERAGE(E27:AH27) -> 0.90739907 | E27: 0.913656 | F27: 0.902025 | G27: 0.906243 | H27: 0.89701 | I27: 0.896194 | J27: 0.896611 | K27: 0.917304 | L27: 0.906194 | M27: 0.866769 | N27: 0.876208 | O27: 0.920634 | P27: 0.903345 | Q27: 0.907927 | R27: 1.091952 | S27: 0.951673 | T27: 0.922403 | U27: 0.917173 | V27: 0.890074 | W27: 0.887109 | X27: 0.918648 | Y27: 0.889111 | Z27: 0.892003 | AA27: 0.879377 | AB27: 0.908708 | AC27: 0.908339 | AD27: 0.887682 | AE27: 0.915948 | AF27: 0.888514 | AG27: 0.877502 | AH27: 0.885636
B28: 2000 | C28: 1 | D28: =AVERAGE(E28:AH28) -> 29.215939 | E28: 28.790833 | F28: 32.697472 | G28: 28.725635 | H28: 31.398026 | I28: 28.669455 | J28: 29.262014 | K28: 29.040017 | L28: 28.846025 | M28: 28.828257 | N28: 29.217551 | O28: 28.869644 | P28: 28.857355 | Q28: 28.868002 | R28: 28.85494 | S28: 28.9666 | T28: 28.861334 | U28: 28.842844 | V28: 29.364803 | W28: 29.950191 | X28: 29.337461 | Y28: 29.559468 | Z28: 29.187816 | AA28: 28.868481 | AB28: 29.161784 | AC28: 28.876238 | AD28: 28.918042 | AE28: 29.041114 | AF28: 28.929512 | AG28: 28.798077 | AH28: 28.889181
C29: 2 | D29: =AVERAGE(E29:AH29) -> 17.347332 | E29: 17.223724 | F29: 17.366514 | G29: 17.274022 | H29: 17.340404 | I29: 17.273719 | J29: 17.25338 | K29: 17.253789 | L29: 17.257229 | M29: 17.27902 | N29: 17.261673 | O29: 17.303181 | P29: 17.400512 | Q29: 17.364369 | R29: 17.628891 | S29: 17.743758 | T29: 17.432284 | U29: 17.39707 | V29: 17.428127 | W29: 17.517563 | X29: 17.339472 | Y29: 17.296671 | Z29: 17.359174 | AA29: 17.309554 | AB29: 17.297516 | AC29: 17.274947 | AD29: 17.279791 | AE29: 17.359968 | AF29: 17.290607 | AG29: 17.278987 | AH29: 17.334057
C30: 4 | D30: =AVERAGE(E30:AH30) -> 11.567781 | E30: 11.600829 | F30: 11.541789 | G30: 11.562903 | H30: 11.549543 | I30: 11.543529 | J30: 11.564116 | K30: 11.564089 | L30: 11.532494 | M30: 11.635542 | N30: 11.543432 | O30: 11.585147 | P30: 11.566869 | Q30: 11.529179 | R30: 11.612631 | S30: 11.565207 | T30: 11.551621 | U30: 11.571081 | V30: 11.570865 | W30: 11.555621 | X30: 11.607903 | Y30: 11.58616 | Z30: 11.569378 | AA30: 11.578374 | AB30: 11.539841 | AC30: 11.534171 | AD30: 11.564932 | AE30: 11.547704 | AF30: 11.6269 | AG30: 11.552711 | AH30: 11.578866
C31: 8 | D31: =AVERAGE(E31:AH31) -> 9.1983194 | E31: 9.116142 | F31: 9.118741 | G31: 9.130575 | H31: 9.184247 | I31: 9.276062 | J31: 9.196779 | K31: 9.250212 | L31: 9.073252 | M31: 9.121159 | N31: 9.269947 | O31: 9.102271 | P31: 9.280027 | Q31: 9.248705 | R31: 9.213373 | S31: 9.213387 | T31: 9.187573 | U31: 9.162381 | V31: 9.274014 | W31: 9.222257 | X31: 9.274402 | Y31: 9.171456 | Z31: 9.12061 | AA31: 9.297123 | AB31: 9.221128 | AC31: 9.406458 | AD31: 9.089825 | AE31: 9.164913 | AF31: 9.195279 | AG31: 9.322138 | AH31: 9.045146
C32: 16 | D32: =AVERAGE(E32:AH32) -> 9.9061937 | E32: 10.16041 | F32: 9.878835 | G32: 9.978289 | H32: 9.863132 | I32: 9.8877 | J32: 9.836729 | K32: 9.810743 | L32: 9.871873 | M32: 9.800008 | N32: 9.958055 | O32: 10.139546 | P32: 9.821337 | Q32: 9.904365 | R32: 9.88897 | S32: 9.837857 | T32: 9.85943 | U32: 9.876291 | V32: 9.887779 | W32: 10.002983 | X32: 9.827355 | Y32: 9.901607 | Z32: 9.810304 | AA32: 10.162087 | AB32: 9.906561 | AC32: 9.90366 | AD32: 9.847737 | AE32: 9.954617 | AF32: 9.86933 | AG32: 9.842881 | AH32: 9.895341
B33: 4000 | C33: 1 | D33: =AVERAGE(E33:AH33) -> 263.37017 | E33: 244.96033 | F33: 253.77284 | G33: 273.35399 | H33: 329.66238 | I33: 280.34269 | J33: 279.62439 | K33: 276.19113 | L33: 288.64862 | M33: 288.00433 | N33: 271.20676 | O33: 277.14628 | P33: 279.18744 | Q33: 258.90441 | R33: 248.69939 | S33: 248.47144 | T33: 247.90786 | U33: 249.57728 | V33: 250.03566 | W33: 275.67234 | X33: 254.98084 | Y33: 260.09803 | Z33: 250.64007 | AA33: 252.90493 | AB33: 250.7553 | AC33: 253.71325 | AD33: 254.1722 | AE33: 250.90069 | AF33: 249.11814 | AG33: 251.11643 | AH33: 251.3356
C34: 2 | D34: =AVERAGE(E34:AH34) -> 155.23923 | E34: 156.17394 | F34: 156.45209 | G34: 154.26699 | H34: 158.92285 | I34: 157.20525 | J34: 153.43439 | K34: 159.58208 | L34: 154.57711 | M34: 153.90511 | N34: 158.08131 | O34: 154.01284 | P34: 158.02496 | Q34: 153.91242 | R34: 156.45693 | S34: 154.76557 | T34: 154.32382 | U34: 154.34285 | V34: 153.82748 | W34: 153.18003 | X34: 153.66367 | Y34: 153.60864 | Z34: 154.85527 | AA34: 155.41435 | AB34: 153.18504 | AC34: 154.48031 | AD34: 152.96809 | AE34: 159.73985 | AF34: 158.22234 | AG34: 153.15689 | AH34: 152.43451
C35: 4 | D35: =AVERAGE(E35:AH35) -> 106.03231 | E35: 105.82223 | F35: 105.73738 | G35: 105.85746 | H35: 105.15264 | I35: 104.74059 | J35: 105.57972 | K35: 105.90614 | L35: 106.53618 | M35: 104.89096 | N35: 105.88716 | O35: 104.9979 | P35: 105.32117 | Q35: 106.02818 | R35: 107.03446 | S35: 105.27077 | T35: 106.91416 | U35: 106.9321 | V35: 105.6857 | W35: 106.43194 | X35: 106.20629 | Y35: 106.13842 | Z35: 106.55746 | AA35: 106.40895 | AB35: 106.60669 | AC35: 106.22502 | AD35: 106.53291 | AE35: 108.06255 | AF35: 105.78776 | AG35: 105.20842 | AH35: 106.50803
C36: 8 | D36: =AVERAGE(E36:AH36) -> 105.74211 | E36: 105.5285 | F36: 105.16977 | G36: 105.54258 | H36: 104.92858 | I36: 104.24667 | J36: 108.09692 | K36: 104.29272 | L36: 105.40857 | M36: 104.78181 | N36: 105.1046 | O36: 106.89319 | P36: 106.85359 | Q36: 103.87511 | R36: 104.4675 | S36: 107.00532 | T36: 105.16679 | U36: 106.45799 | V36: 106.87284 | W36: 105.25628 | X36: 105.55331 | Y36: 105.50198 | Z36: 104.3098 | AA36: 104.27643 | AB36: 108.33754 | AC36: 105.67147 | AD36: 107.17658 | AE36: 105.09933 | AF36: 106.58202 | AG36: 105.97628 | AH36: 107.82906
C37: 16 | D37: =AVERAGE(E37:AH37) -> 99.094983 | E37: 98.339534 | F37: 102.39226 | G37: 103.87987 | H37: 102.35464 | I37: 101.80532 | J37: 98.505187 | K37: 99.086397 | L37: 101.5532 | M37: 98.152675 | N37: 96.412432 | O37: 96.893479 | P37: 97.058527 | Q37: 97.646886 | R37: 98.248344 | S37: 98.692925 | T37: 97.498825 | U37: 97.286708 | V37: 107.27855 | W37: 100.07695 | X37: 98.426176 | Y37: 97.502588 | Z37: 98.355771 | AA37: 99.026718 | AB37: 97.438418 | AC37: 97.996453 | AD37: 98.870157 | AE37: 98.665815 | AF37: 97.514981 | AG37: 98.28797 | AH37: 97.601716
A38: mmClasicaOpenMP (s) | B38: 1000 | C38: 1 | D38: =AVERAGE(E38:AH38) -> 0.85255323 | E38: 0.844162 | F38: 0.844397 | G38: 0.8456 | H38: 0.85162 | I38: 0.848394 | J38: 0.854451 | K38: 0.858056 | L38: 0.839774 | M38: 0.855585 | N38: 0.846442 | O38: 0.854882 | P38: 0.85942 | Q38: 0.839266 | R38: 0.848689 | S38: 0.849935 | T38: 0.854484 | U38: 0.861345 | V38: 0.853633 | W38: 0.844199 | X38: 0.852311 | Y38: 0.859446 | Z38: 0.85404 | AA38: 0.863553 | AB38: 0.857555 | AC38: 0.854737 | AD38: 0.856431 | AE38: 0.859978 | AF38: 0.858237 | AG38: 0.854197 | AH38: 0.851778
C39: 2 | D39: =AVERAGE(E39:AH39) -> 0.55631907 | E39: 0.565426 | F39: 0.553261 | G39: 0.554947 | H39: 0.556952 | I39: 0.551674 | J39: 0.5613 | K39: 0.555087 | L39: 0.551624 | M39: 0.553222 | N39: 0.554123 | O39: 0.557062 | P39: 0.558481 | Q39: 0.553945 | R39: 0.54963 | S39: 0.547598 | T39: 0.559567 | U39: 0.558777 | V39: 0.552417 | W39: 0.55584 | X39: 0.557152 | Y39: 0.563583 | Z39: 0.55555 | AA39: 0.549324 | AB39: 0.566173 | AC39: 0.555715 | AD39: 0.56545 | AE39: 0.563236 | AF39: 0.557048 | AG39: 0.554587 | AH39: 0.550821
C40: 4 | D40: =AVERAGE(E40:AH40) -> 0.4028276 | E40: 0.388118 | F40: 0.400557 | G40: 0.4007 | H40: 0.398232 | I40: 0.397731 | J40: 0.401258 | K40: 0.397571 | L40: 0.39784 | M40: 0.405958 | N40: 0.40147 | O40: 0.394933 | P40: 0.393234 | Q40: 0.393126 | R40: 0.39952 | S40: 0.402694 | T40: 0.403889 | U40: 0.406179 | V40: 0.400929 | W40: 0.400098 | X40: 0.395942 | Y40: 0.395718 | Z40: 0.39023 | AA40: 0.396853 | AB40: 0.397928 | AC40: 0.401177 | AD40: 0.39845 | AE40: 0.524058 | AF40: 0.39746 | AG40: 0.399363 | AH40: 0.403612
C41: 8 | D41: =AVERAGE(E41:AH41) -> 0.39467367 | E41: 0.400723 | F41: 0.394112 | G41: 0.382222 | H41: 0.38271 | I41: 0.394923 | J41: 0.39371 | K41: 0.396683 | L41: 0.412483 | M41: 0.403884 | N41: 0.395589 | O41: 0.396182 | P41: 0.399243 | Q41: 0.396247 | R41: 0.384524 | S41: 0.383421 | T41: 0.399925 | U41: 0.391924 | V41: 0.400851 | W41: 0.39766 | X41: 0.389557 | Y41: 0.402661 | Z41: 0.396942 | AA41: 0.399728 | AB41: 0.396073 | AC41: 0.384529 | AD41: 0.388135 | AE41: 0.385727 | AF41: 0.393225 | AG41: 0.398315 | AH41: 0.398302
C42: 16 | D42: =AVERAGE(E42:AH42) -> 0.39026837 | E42: 0.403157 | F42: 0.391113 | G42: 0.395585 | H42: 0.390299 | I42: 0.389364 | J42: 0.384658 | K42: 0.388848 | L42: 0.385949 | M42: 0.387956 | N42: 0.38353 | O42: 0.388813 | P42: 0.383825 | Q42: 0.388544 | R42: 0.397316 | S42: 0.39602 | T42: 0.385914 | U42: 0.389069 | V42: 0.382727 | W42: 0.382967 | X42: 0.39138 | Y42: 0.380557 | Z42: 0.393232 | AA42: 0.386841 | AB42: 0.393532 | AC42: 0.406823 | AD42: 0.393338 | AE42: 0.396941 | AF42: 0.389305 | AG42: 0.392582 | AH42: 0.387866
B43: 2000 | C43: 1 | D43: =AVERAGE(E43:AH43) -> 11.179702 | E43: 11.088046 | F43: 12.093377 | G43: 11.946952 | H43: 11.923216 | I43: 11.086385 | J43: 11.186566 | K43: 11.056782 | L43: 11.037508 | M43: 10.957324 | N43: 11.027581 | O43: 11.038409 | P43: 11.010277 | Q43: 11.024141 | R43: 11.419811 | S43: 11.457186 | T43: 10.995088 | U43: 11.042973 | V43: 10.998209 | W43: 11.126568 | X43: 10.938626 | Y43: 11.059332 | Z43: 10.967379 | AA43: 11.078491 | AB43: 11.007545 | AC43: 11.016711 | AD43: 11.057756 | AE43: 11.191583 | AF43: 11.489692 | AG43: 11.012228 | AH43: 11.055322
C44: 2 | D44: =AVERAGE(E44:AH44) -> 7.131837 | E44: 7.067765 | F44: 7.085929 | G44: 7.091973 | H44: 7.09728 | I44: 7.17707 | J44: 7.111451 | K44: 7.173309 | L44: 7.160969 | M44: 7.126434 | N44: 7.106343 | O44: 7.139046 | P44: 7.185954 | Q44: 7.156939 | R44: 7.151574 | S44: 7.107683 | T44: 7.117525 | U44: 7.137657 | V44: 7.131465 | W44: 7.260239 | X44: 7.136945 | Y44: 7.104405 | Z44: 7.104975 | AA44: 7.155785 | AB44: 7.108649 | AC44: 7.112188 | AD44: 7.107083 | AE44: 7.175655 | AF44: 7.106139 | AG44: 7.152577 | AH44: 7.104103
C45: 4 | D45: =AVERAGE(E45:AH45) -> 4.8582227 | E45: 4.941389 | F45: 4.847284 | G45: 4.843386 | H45: 4.825294 | I45: 4.844083 | J45: 4.836883 | K45: 4.824411 | L45: 4.827438 | M45: 4.855497 | N45: 4.833781 | O45: 4.859134 | P45: 4.83743 | Q45: 4.845944 | R45: 4.853551 | S45: 4.842424 | T45: 4.829349 | U45: 4.931068 | V45: 5.139183 | W45: 4.831451 | X45: 4.843036 | Y45: 4.832933 | Z45: 4.821597 | AA45: 4.8243 | AB45: 4.838161 | AC45: 4.875174 | AD45: 4.869011 | AE45: 4.858678 | AF45: 4.849005 | AG45: 4.837264 | AH45: 4.848542
...

Sheet Rendimiento_PC_3
B4: Calculo de Rendimiento Promedio con Matrices e hilos definidos en segundos | F4: PC 3
B7: Matrices | C7: Hilos | D7: Promedio | E7: Iter1 | F7: Iter2 | G7: Iter3 | H7: Iter4 | I7: Iter5 | J7: Iter6 | K7: Iter7 | L7: Iter8 | M7: Iter9 | N7: Iter10 | O7: Iter11 | P7: Iter12 | Q7: Iter13 | R7: Iter14 | S7: Iter15 | T7: Iter16 | U7: Iter17 | V7: Iter18 | W7: Iter19 | X7: Iter20 | Y7: Iter21 | Z7: Iter22 | AA7: Iter23 | AB7: Iter24 | AC7: Iter25 | AD7: Iter26 | AE7: Iter27 | AF7: Iter28 | AG7: Iter29 | AH7: Iter30
A8: mmClasicaFork (s) | B8: 1000 | C8: 1 | D8: =AVERAGE(E8:AH8) -> 4.4296479 | E8: 4.895675 | F8: 3.544008 | G8: 4.882682 | H8: 4.348429 | I8: 3.874759 | J8: 4.54977 | K8: 4.558123 | L8: 4.518869 | M8: 4.475893 | N8: 4.375157 | O8: 4.44104 | P8: 4.486574 | Q8: 4.534959 | R8: 4.458364 | S8: 4.44561 | T8: 4.424964 | U8: 4.405927 | V8: 4.434014 | W8: 4.457507 | X8: 4.548449 | Y8: 4.454075 | Z8: 4.393736 | AA8: 4.380511 | AB8: 4.524613 | AC8: 4.433263 | AD8: 4.304929 | AE8: 4.466288 | AF8: 4.377879 | AG8: 4.444042 | AH8: 4.449329
C9: 2 | D9: =AVERAGE(E9:AH9) -> 2.1563045 | E9: 2.219862 | F9: 2.116584 | G9: 2.165206 | H9: 2.171408 | I9: 2.158597 | J9: 2.177241 | K9: 2.119986 | L9: 2.211342 | M9: 2.301726 | N9: 2.14151 | O9: 2.069254 | P9: 2.095806 | Q9: 2.173586 | R9: 2.120024 | S9: 2.133883 | T9: 2.211637 | U9: 2.26039 | V9: 2.108886 | W9: 2.132702 | X9: 2.151631 | Y9: 2.142218 | Z9: 2.13936 | AA9: 2.385598 | AB9: 2.118608 | AC9: 2.160831 | AD9: 2.079191 | AE9: 2.107107 | AF9: 2.09261 | AG9: 2.072314 | AH9: 2.150036
C10: 4 | D10: =AVERAGE(E10:AH10) -> 1.019896 | E10: 1.063269 | F10: 1.015322 | G10: 1.007491 | H10: 1.004065 | I10: 1.017159 | J10: 1.0147 | K10: 1.04487 | L10: 1.026107 | M10: 1.029957 | N10: 1.01907 | O10: 1.009003 | P10: 1.005763 | Q10: 1.026499 | R10: 1.026359 | S10: 1.013974 | T10: 1.010705 | U10: 1.022954 | V10: 1.016322 | W10: 1.008773 | X10: 1.00905 | Y10: 1.064425 | Z10: 1.031053 | AA10: 1.010489 | AB10: 1.012962 | AC10: 1.012917 | AD10: 1.023786 | AE10: 1.014882 | AF10: 1.00254 | AG10: 1.027648 | AH10: 1.004765
C11: 8 | D11: =AVERAGE(E11:AH11) -> 1.0115513 | E11: 1.017933 | F11: 0.96037 | G11: 1.032878 | H11: 1.031654 | I11: 0.9751 | J11: 1.024966 | K11: 1.02188 | L11: 1.027311 | M11: 1.014432 | N11: 0.985175 | O11: 0.95621 | P11: 0.9846 | Q11: 1.022431 | R11: 0.96256 | S11: 1.021104 | T11: 1.047453 | U11: 1.013649 | V11: 1.011638 | W11: 1.016392 | X11: 0.974027 | Y11: 0.969355 | Z11: 1.016404 | AA11: 1.026439 | AB11: 1.038225 | AC11: 1.045455 | AD11: 1.058814 | AE11: 0.993787 | AF11: 1.025821 | AG11: 1.042912 | AH11: 1.027564
C12: 16 | D12: =AVERAGE(E12:AH12) -> 1.0302299 | E12: 1.016655 | F12: 0.967014 | G12: 0.976216 | H12: 1.054019 | I12: 1.004761 | J12: 1.060799 | K12: 1.050977 | L12: 1.050158 | M12: 1.054721 | N12: 0.993527 | O12: 0.967265 | P12: 1.043327 | Q12: 1.076541 | R12: 1.06279 | S12: 1.021318 | T12: 1.045747 | U12: 1.035364 | V12: 0.976172 | W12: 1.057653 | X12: 1.069431 | Y12: 1.047171 | Z12: 1.043317 | AA12: 1.059864 | AB12: 0.956848 | AC12: 1.023162 | AD12: 1.037303 | AE12: 1.025758 | AF12: 1.061663 | AG12: 1.036047 | AH12: 1.031309
B13: 2000 | C13: 1 | D13: =AVERAGE(E13:AH13) -> 48.328844 | E13: 48.892947 | F13: 48.320069 | G13: 50.712014 | H13: 45.849341 | I13: 47.088149 | J13: 49.007171 | K13: 47.878933 | L13: 48.24662 | M13: 47.050474 | N13: 47.720657 | O13: 46.982677 | P13: 51.247662 | Q13: 48.448391 | R13: 47.774984 | S13: 45.823218 | T13: 52.615127 | U13: 46.74346 | V13: 48.273949 | W13: 51.66721 | X13: 46.51422 | Y13: 45.016237 | Z13: 49.495935 | AA13: 49.1155 | AB13: 46.522632 | AC13: 48.11271 | AD13: 47.983281 | AE13: 47.184108 | AF13: 48.976375 | AG13: 51.5649 | AH13: 49.036373
C14: 2 | D14: =AVERAGE(E14:AH14) -> 24.904403 | E14: 24.921109 | F14: 26.027854 | G14: 24.998351 | H14: 24.124261 | I14: 26.522389 | J14: 23.025408 | K14: 25.750421 | L14: 25.876239 | M14: 24.081175 | N14: 23.834626 | O14: 25.498155 | P14: 25.887864 | Q14: 24.977038 | R14: 26.548337 | S14: 24.155694 | T14: 23.338014 | U14: 24.973732 | V14: 25.072149 | W14: 25.167857 | X14: 25.130497 | Y14: 24.062511 | Z14: 22.523541 | AA14: 24.021353 | AB14: 23.884564 | AC14: 25.868425 | AD14: 26.004326 | AE14: 25.177475 | AF14: 25.289678 | AG14: 25.263002 | AH14: 25.126035
C15: 4 | D15: =AVERAGE(E15:AH15) -> 12.400948 | E15: 12.615816 | F15: 12.315232 | G15: 12.453484 | H15: 12.744252 | I15: 12.107526 | J15: 12.381531 | K15: 12.565343 | L15: 11.730083 | M15: 12.333455 | N15: 12.770208 | O15: 12.646901 | P15: 12.011872 | Q15: 11.764396 | R15: 12.568385 | S15: 12.795002 | T15: 12.319965 | U15: 12.16258 | V15: 12.693324 | W15: 12.900906 | X15: 12.38356 | Y15: 12.823616 | Z15: 12.573542 | AA15: 12.737965 | AB15: 11.887287 | AC15: 12.36314 | AD15: 12.354934 | AE15: 12.073764 | AF15: 12.978706 | AG15: 11.58029 | AH15: 12.391376
C16: 8 | D16: =AVERAGE(E16:AH16) -> 11.578498 | E16: 10.900333 | F16: 11.645832 | G16: 11.855089 | H16: 11.132054 | I16: 11.969806 | J16: 11.916684 | K16: 10.92035 | L16: 11.84096 | M16: 12.222705 | N16: 11.056685 | O16: 12.123046 | P16: 11.597794 | Q16: 11.738605 | R16: 11.294058 | S16: 11.807159 | T16: 11.365529 | U16: 11.302934 | V16: 11.314886 | W16: 11.659459 | X16: 11.621287 | Y16: 10.994833 | Z16: 11.308213 | AA16: 11.824875 | AB16: 11.305539 | AC16: 11.832618 | AD16: 11.611953 | AE16: 11.362556 | AF16: 12.002658 | AG16: 12.126085 | AH16: 11.700366
C17: 16 | D17: =AVERAGE(E17:AH17) -> 11.460496 | E17: 11.546866 | F17: 12.07663 | G17: 12.009851 | H17: 11.19186 | I17: 11.494085 | J17: 11.825036 | K17: 11.223098 | L17: 11.659629 | M17: 11.357532 | N17: 11.166707 | O17: 10.757526 | P17: 11.622568 | Q17: 11.651915 | R17: 10.470928 | S17: 11.882646 | T17: 11.639362 | U17: 11.62093 | V17: 11.697395 | W17: 11.007373 | X17: 11.05061 | Y17: 11.501774 | Z17: 11.017885 | AA17: 11.676422 | AB17: 12.079645 | AC17: 10.996758 | AD17: 12.101214 | AE17: 12.222651 | AF17: 11.389467 | AG17: 10.504226 | AH17: 11.37229
B18: 4000 | C18: 1 | D18: =AVERAGE(E18:AH18) -> 663.00071 | E18: 653.08754 | F18: 641.84152 | G18: 651.17536 | H18: 650.65004 | I18: 639.01595 | J18: 646.946 | K18: 682.41648 | L18: 649.88105 | M18: 644.51779 | N18: 626.03643 | O18: 689.03215 | P18: 697.53439 | Q18: 673.65839 | R18: 676.4314 | S18: 674.07768 | T18: 666.87789 | U18: 690.27563 | V18: 656.46949 | W18: 658.14514 | X18: 665.46989 | Y18: 663.69932 | Z18: 665.26256 | AA18: 652.3325 | AB18: 668.12593 | AC18: 661.86853 | AD18: 675.0641 | AE18: 681.96462 | AF18: 655.00446 | AG18: 666.58678 | AH18: 666.57232
C19: 2 | D19: =AVERAGE(E19:AH19) -> 330.03593 | E19: 336.29147 | F19: 341.31596 | G19: 331.82544 | H19: 340.87986 | I19: 330.29411 | J19: 329.64927 | K19: 327.63582 | L19: 342.17532 | M19: 339.13725 | N19: 331.28907 | O19: 327.74612 | P19: 340.71278 | Q19: 327.72388 | R19: 323.82816 | S19: 327.69109 | T19: 334.07147 | U19: 325.152 | V19: 333.16465 | W19: 330.37439 | X19: 316.22414 | Y19: 330.81365 | Z19: 322.72287 | AA19: 330.77372 | AB19: 320.70958 | AC19: 318.39059 | AD19: 317.31723 | AE19: 324.54733 | AF19: 339.35475 | AG19: 329.08488 | AH19: 330.18098
C20: 4 | D20: =AVERAGE(E20:AH20) -> 161.7735 | E20: 164.29695 | F20: 163.72076 | G20: 170.60604 | H20: 166.70043 | I20: 166.72018 | J20: 165.36703 | K20: 160.53523 | L20: 160.23869 | M20: 157.50168 | N20: 159.59779 | O20: 162.91941 | P20: 159.87766 | Q20: 155.46178 | R20: 158.64697 | S20: 165.81925 | T20: 162.06191 | U20: 160.01067 | V20: 156.94544 | W20: 163.27878 | X20: 154.45887 | Y20: 165.03814 | Z20: 158.11931 | AA20: 165.63584 | AB20: 159.77886 | AC20: 161.15666 | AD20: 162.05445 | AE20: 162.51894 | AF20: 163.00232 | AG20: 160.5147 | AH20: 160.62031
C21: 8 | D21: =AVERAGE(E21:AH21) -> 159.41807 | E21: 155.35494 | F21: 155.64541 | G21: 158.80439 | H21: 152.92198 | I21: 158.73879 | J21: 158.32695 | K21: 156.2488 | L21: 160.10506 | M21: 160.2222 | N21: 159.46316 | O21: 162.60511 | P21: 164.32664 | Q21: 166.03032 | R21: 163.93685 | S21: 160.05061 | T21: 155.07515 | U21: 162.78993 | V21: 158.05141 | W21: 159.81662 | X21: 160.39689 | Y21: 161.23131 | Z21: 161.73759 | AA21: 160.71168 | AB21: 157.66965 | AC21: 160.51944 | AD21: 157.99614 | AE21: 157.37776 | AF21: 162.33546 | AG21: 158.71435 | AH21: 155.33744
